<?xml version="1.0" encoding="utf-8"?>
<!-- This URDF was automatically created by SolidWorks to URDF Exporter! Originally created by Stephen Brawner (brawner@gmail.com) 
     Commit Version: 1.6.0-4-g7f85cfe  Build Version: 1.6.7995.38578
     For more information, please see http://wiki.ros.org/sw_urdf_exporter -->
<robot
  name="testarm_urdf">
  <link
    name="base_link">
    <inertial>
      <origin
        xyz="2.7756E-17 1.1102E-16 0.10722"
        rpy="0 0 0" />
      <mass
        value="667.25" />
      <inertia
        ixx="21.308"
        ixy="3.2909E-08"
        ixz="4.2875E-16"
        iyy="21.308"
        iyz="-5.9757E-16"
        izz="36.305" />
    </inertial>
    <visual>
      <origin
        xyz="0 0 0"
        rpy="0 0 0" />
      <geometry>
        <mesh
          filename="package://testarm_urdf/meshes/base_link.STL" />
      </geometry>
      <material
        name="">
        <color
          rgba="0.61961 0.40784 0.2 1" />
      </material>
    </visual>
    <collision>
      <origin
        xyz="0 0 0"
        rpy="0 0 0" />
      <geometry>
        <mesh
          filename="package://testarm_urdf/meshes/base_link.STL" />
      </geometry>
    </collision>
  </link>
  <link
    name="l1">
    <inertial>
      <origin
        xyz="2.06E-05 -0.22592 0.1524"
        rpy="0 0 0" />
      <mass
        value="103.33" />
      <inertia
        ixx="2.3418"
        ixy="0.00010868"
        ixz="6.0067E-07"
        iyy="1.6131"
        iyz="1.2951E-06"
        izz="1.8272" />
    </inertial>
    <visual>
      <origin
        xyz="0 0 0"
        rpy="0 0 0" />
      <geometry>
        <mesh
          filename="package://testarm_urdf/meshes/l1.STL" />
      </geometry>
      <material
        name="">
        <color
          rgba="0.77647 0.75686 0.73725 1" />
      </material>
    </visual>
    <collision>
      <origin
        xyz="0 0 0"
        rpy="0 0 0" />
      <geometry>
        <mesh
          filename="package://testarm_urdf/meshes/l1.STL" />
      </geometry>
    </collision>
  </link>
  <joint
    name="j1"
    type="revolute">
    <origin
      xyz="0 0.1524 0.59921"
      rpy="1.5708 0 0" />
    <parent
      link="base_link" />
    <child
      link="l1" />
    <axis
      xyz="0 0 0" />
    <limit
      lower="0"
      upper="3.142"
      effort="300"
      velocity="3" />
  </joint>
  <link
    name="l2">
    <inertial>
      <origin
        xyz="4.3999E-12 -0.1558 0.10012"
        rpy="0 0 0" />
      <mass
        value="141.23" />
      <inertia
        ixx="2.7406"
        ixy="-3.9887E-10"
        ixz="9.097E-10"
        iyy="1.1047"
        iyz="-0.011982"
        izz="2.7555" />
    </inertial>
    <visual>
      <origin
        xyz="0 0 0"
        rpy="0 0 0" />
      <geometry>
        <mesh
          filename="package://testarm_urdf/meshes/l2.STL" />
      </geometry>
      <material
        name="">
        <color
          rgba="0.64706 0.61961 0.58824 1" />
      </material>
    </visual>
    <collision>
      <origin
        xyz="0 0 0"
        rpy="0 0 0" />
      <geometry>
        <mesh
          filename="package://testarm_urdf/meshes/l2.STL" />
      </geometry>
    </collision>
  </link>
  <joint
    name="j2"
    type="revolute">
    <origin
      xyz="0 0.254 0.0508"
      rpy="0 0 0" />
    <parent
      link="l1" />
    <child
      link="l2" />
    <axis
      xyz="0 0 0" />
    <limit
      lower="-1.57"
      upper="1.57"
      effort="200"
      velocity="3" />
  </joint>
  <link
    name="l3">
    <inertial>
      <origin
        xyz="0 -0.0352868391760749 0.152407642498591"
        rpy="0 0 0" />
      <mass
        value="339.624762377846" />
      <inertia
        ixx="16.1407171180524"
        ixy="8.62670971937533E-16"
        ixz="-8.54402881463985E-17"
        iyy="5.11372188592373"
        iyz="-0.000699793193465693"
        izz="14.5610784866681" />
    </inertial>
    <visual>
      <origin
        xyz="0 0 0"
        rpy="0 0 0" />
      <geometry>
        <mesh
          filename="package://testarm_urdf/meshes/l3.STL" />
      </geometry>
      <material
        name="">
        <color
          rgba="0.776470588235294 0.756862745098039 0.737254901960784 1" />
      </material>
    </visual>
    <collision>
      <origin
        xyz="0 0 0"
        rpy="0 0 0" />
      <geometry>
        <mesh
          filename="package://testarm_urdf/meshes/l3.STL" />
      </geometry>
    </collision>
  </link>
  <joint
    name="j3"
    type="revolute">
    <origin
      xyz="-0.34822 0 -0.0508"
      rpy="0 0 1.5708" />
    <parent
      link="l2" />
    <child
      link="l3" />
    <axis
      xyz="0 0 0" />
    <limit
      lower="-1.57"
      upper="1.57"
      effort="200"
      velocity="3" />
  </joint>
</robot>